<?xml version="1.0" encoding="UTF-8"?>
<testsuites>
	<testsuite errors="0" failures="1" file=".py" name="InterfaceTest-20190731132736" skipped="0" tests="8" time="0.911" timestamp="2019-07-31T13:27:37">
		<testcase classname="InterfaceTest" file="apps\testtask\extend\run_task.py" line="24" name="test_run_cases_00001_45" time="0.202" timestamp="2019-07-31T13:27:36">
			<system-out>
<![CDATA[]]>			</system-out>
			<system-err>
<![CDATA[]]>			</system-err>
		</testcase>
		<testcase classname="InterfaceTest" file="apps\testtask\extend\run_task.py" line="24" name="test_run_cases_00002_48" time="0.099" timestamp="2019-07-31T13:27:36">
			<system-out>
<![CDATA[]]>			</system-out>
			<system-err>
<![CDATA[]]>			</system-err>
		</testcase>
		<testcase classname="InterfaceTest" file="apps\testtask\extend\run_task.py" line="24" name="test_run_cases_00003_68" time="0.098" timestamp="2019-07-31T13:27:36">
			<system-out>
<![CDATA[]]>			</system-out>
			<system-err>
<![CDATA[]]>			</system-err>
		</testcase>
		<testcase classname="InterfaceTest" file="apps\testtask\extend\run_task.py" line="24" name="test_run_cases_00004_70" time="0.109" timestamp="2019-07-31T13:27:36">
			<system-out>
<![CDATA[]]>			</system-out>
			<system-err>
<![CDATA[]]>			</system-err>
		</testcase>
		<testcase classname="InterfaceTest" file="apps\testtask\extend\run_task.py" line="24" name="test_run_cases_00005_71" time="0.095" timestamp="2019-07-31T13:27:36">
			<system-out>
<![CDATA[]]>			</system-out>
			<system-err>
<![CDATA[]]>			</system-err>
		</testcase>
		<testcase classname="InterfaceTest" file="apps\testtask\extend\run_task.py" line="24" name="test_run_cases_00007_73" time="0.115" timestamp="2019-07-31T13:27:36">
			<system-out>
<![CDATA[]]>			</system-out>
			<system-err>
<![CDATA[]]>			</system-err>
		</testcase>
		<testcase classname="InterfaceTest" file="apps\testtask\extend\run_task.py" line="24" name="test_run_cases_00008_74" time="0.099" timestamp="2019-07-31T13:27:37">
			<system-out>
<![CDATA[]]>			</system-out>
			<system-err>
<![CDATA[]]>			</system-err>
		</testcase>
		<testcase classname="InterfaceTest" file="apps\testtask\extend\run_task.py" line="24" name="test_run_cases_00006_72" time="0.095" timestamp="2019-07-31T13:27:36">
			<failure message="'&quot;interaction_type&quot;: &quot;7&quot;' not found in '[{&quot;ads&quot;: [], &quot;bid&quot;: &quot;c88b655c6c9de20dd3009f36434dddvv&quot;, &quot;error_code&quot;: 0, &quot;error_msg&quot;: &quot;mal:&quot;, &quot;backup&quot;: 0, &quot;backups&quot;: [], &quot;third_tracking&quot;: null, &quot;cache_assets&quot;: null}, 0.042936]'" type="AssertionError">
<![CDATA[Traceback (most recent call last):
  File "D:\UserData\Program\Python36\lib\site-packages\ddt.py", line 146, in wrapper
    return func(self, *args, **kwargs)
  File "D:\UserData\git\PycharmProjects\apitest_platform\test_platform\apps/testtask/extend/run_task.py", line 99, in test_run_cases
    self.assertIn( assert_str, result_text )
AssertionError: '"interaction_type": "7"' not found in '[{"ads": [], "bid": "c88b655c6c9de20dd3009f36434dddvv", "error_code": 0, "error_msg": "mal:", "backup": 0, "backups": [], "third_tracking": null, "cache_assets": null}, 0.042936]'
]]>			</failure>
			<system-out>
<![CDATA[]]>			</system-out>
			<system-err>
<![CDATA[]]>			</system-err>
		</testcase>
	</testsuite>
</testsuites>
